[["file:///home/jfvilladiego/proyectos_laravel/cotizaciones_vcb_laravel/vendor/phpunit/phpunit/src/Framework/TestFailure.php",{"_uri":"file:///home/jfvilladiego/proyectos_laravel/cotizaciones_vcb_laravel/vendor/phpunit/phpunit/src/Framework/TestFailure.php","_root":{"kind":4096,"name":"file:///home/jfvilladiego/proyectos_laravel/cotizaciones_vcb_laravel/vendor/phpunit/phpunit/src/Framework/TestFailure.php","location":{"uriHash":2146347780,"range":{"start":{"line":0,"character":0},"end":{"line":161,"character":0}}},"children":[{"kind":1,"name":"PHPUnit_Framework_TestFailure","location":{"uriHash":2146347780,"range":{"start":{"line":13,"character":0},"end":{"line":160,"character":1}}},"children":[{"kind":16,"name":"$testName","location":{"uriHash":2146347780,"range":{"start":{"line":18,"character":12},"end":{"line":18,"character":21}}},"doc":{"description":"","type":"string"},"modifiers":4,"scope":"PHPUnit_Framework_TestFailure"},{"kind":16,"name":"$failedTest","location":{"uriHash":2146347780,"range":{"start":{"line":23,"character":14},"end":{"line":23,"character":25}}},"doc":{"description":"","type":"PHPUnit_Framework_Test|null"},"modifiers":2,"scope":"PHPUnit_Framework_TestFailure"},{"kind":16,"name":"$thrownException","location":{"uriHash":2146347780,"range":{"start":{"line":28,"character":14},"end":{"line":28,"character":30}}},"doc":{"description":"","type":"Exception"},"modifiers":2,"scope":"PHPUnit_Framework_TestFailure"},{"kind":32,"name":"__construct","location":{"uriHash":2146347780,"range":{"start":{"line":36,"character":4},"end":{"line":49,"character":5}}},"doc":{"description":"Constructs a TestFailure with the given test and exception.","type":""},"modifiers":1,"type":"","children":[{"kind":128,"name":"$failedTest","location":{"uriHash":2146347780,"range":{"start":{"line":36,"character":32},"end":{"line":36,"character":66}}},"type":"PHPUnit_Framework_Test","doc":{"description":"","type":"PHPUnit_Framework_Test"},"scope":"__construct"},{"kind":128,"name":"$t","location":{"uriHash":2146347780,"range":{"start":{"line":36,"character":68},"end":{"line":36,"character":70}}},"doc":{"description":"","type":"Throwable"},"scope":"__construct"}],"scope":"PHPUnit_Framework_TestFailure"},{"kind":32,"name":"toString","location":{"uriHash":2146347780,"range":{"start":{"line":56,"character":4},"end":{"line":63,"character":5}}},"doc":{"description":"Returns a short description of the failure.","type":"string"},"modifiers":1,"type":"","children":[],"scope":"PHPUnit_Framework_TestFailure"},{"kind":32,"name":"getExceptionAsString","location":{"uriHash":2146347780,"range":{"start":{"line":70,"character":4},"end":{"line":73,"character":5}}},"doc":{"description":"Returns a description for the thrown exception.","type":"string"},"modifiers":1,"type":"","children":[],"scope":"PHPUnit_Framework_TestFailure"},{"kind":32,"name":"exceptionToString","location":{"uriHash":2146347780,"range":{"start":{"line":82,"character":4},"end":{"line":103,"character":5}}},"doc":{"description":"Returns a description for an exception.","type":"string"},"modifiers":33,"type":"","children":[{"kind":128,"name":"$e","location":{"uriHash":2146347780,"range":{"start":{"line":82,"character":45},"end":{"line":82,"character":57}}},"type":"Exception","doc":{"description":"","type":"Exception"},"scope":"exceptionToString"}],"scope":"PHPUnit_Framework_TestFailure"},{"kind":32,"name":"getTestName","location":{"uriHash":2146347780,"range":{"start":{"line":110,"character":4},"end":{"line":113,"character":5}}},"doc":{"description":"Returns the name of the failing test (including data set, if any).","type":"string"},"modifiers":1,"type":"","children":[],"scope":"PHPUnit_Framework_TestFailure"},{"kind":32,"name":"failedTest","location":{"uriHash":2146347780,"range":{"start":{"line":125,"character":4},"end":{"line":128,"character":5}}},"doc":{"description":"Returns the failing test.\n\nNote: The test object is not set when the test is executed in process\nisolation.","type":"PHPUnit_Framework_Test|null"},"modifiers":1,"type":"","children":[],"scope":"PHPUnit_Framework_TestFailure"},{"kind":32,"name":"thrownException","location":{"uriHash":2146347780,"range":{"start":{"line":135,"character":4},"end":{"line":138,"character":5}}},"doc":{"description":"Gets the thrown exception.","type":"Exception"},"modifiers":1,"type":"","children":[],"scope":"PHPUnit_Framework_TestFailure"},{"kind":32,"name":"exceptionMessage","location":{"uriHash":2146347780,"range":{"start":{"line":145,"character":4},"end":{"line":148,"character":5}}},"doc":{"description":"Returns the exception's message.","type":"string"},"modifiers":1,"type":"","children":[],"scope":"PHPUnit_Framework_TestFailure"},{"kind":32,"name":"isFailure","location":{"uriHash":2146347780,"range":{"start":{"line":156,"character":4},"end":{"line":159,"character":5}}},"doc":{"description":"Returns true if the thrown exception\nis of type AssertionFailedError.","type":"bool"},"modifiers":1,"type":"","children":[],"scope":"PHPUnit_Framework_TestFailure"}],"associated":[],"doc":{"description":"A TestFailure collects a failed test together with the caught exception.","type":""},"modifiers":0}]},"_hash":2146347780}]]